Workbook

Sheet BAU>

Sheet BAU v.1
A1: Notes: - Figures + assumptions are spead in the same sheet. - You can use this format if there are not many line items to be shown. ('Line item' = Revenue, COGS, etc., basically the things you see on the 'vertical' axis.)
A3: Income Statement
A4: Figures in USD millions unless otherwise stated
B6: 2012A | C6: 2013A | D6: 2014A | E6: 2015E | F6: 2016E | G6: 2017E | H6: 2018E | I6: 2019E | K6: Assumptions
A8: Revenue | B8: 1000 | C8: 1100 | D8: 1200 | E8: =D8*(100%+E9) -> 1314.5455 | F8: =E8*(1+F9) -> 1437.0372 | G8: =F8*(1+G9) -> 1572.5759 | H8: =G8*(1+H9) -> 1720.0049 | I8: =H8*(1+I9) -> 1881.744
A9: % y-o-y growth | C9: =C8/B8-1 -> 0.1 | D9: =D8/C8-1 -> 0.090909091 | E9: =AVERAGE(C9:D9) -> 0.095454545 | F9: =AVERAGE(D9:E9) -> 0.093181818 | G9: =AVERAGE(E9:F9) -> 0.094318182 | H9: =AVERAGE(F9:G9) -> 0.09375 | I9: =AVERAGE(G9:H9) -> 0.094034091 | K9: y-o-y growth; 2Y moving average
A11: COGS | B11: 500 | C11: 550 | D11: 580 | E11: =E8*E12 -> 649.9697 | F11: =F8*F12 -> 710.53506 | G11: =G8*G12 -> 777.55143 | H11: =H8*H12 -> 850.44688 | I11: =I8*I12 -> 930.41788
A12: % of revenue | B12: =B11/B8 -> 0.5 | C12: =C11/C8 -> 0.5 | D12: =D11/D8 -> 0.48333333 | E12: =AVERAGE(B12:D12) -> 0.49444444 | F12: =E12 -> 0.49444444 | G12: =F12 -> 0.49444444 | H12: =G12 -> 0.49444444 | I12: =H12 -> 0.49444444 | K12: % of revenue; simple average from 2012A-2014A
A14: Gross Profit | B14: =B8-B11 -> 500 | C14: =C8-C11 -> 550 | D14: =D8-D11 -> 620 | E14: =E8-E11 -> 664.57576 | F14: =F8-F11 -> 726.50213 | G14: =G8-G11 -> 795.0245 | H14: =H8-H11 -> 869.55804 | I14: =I8-I11 -> 951.32614
A15: % of revenue | B15: =B14/B8 -> 0.5 | C15: =C14/C8 -> 0.5 | D15: =D14/D8 -> 0.51666667 | E15: =E14/E8 -> 0.50555556 | F15: =F14/F8 -> 0.50555556 | G15: =G14/G8 -> 0.50555556 | H15: =H14/H8 -> 0.50555556 | I15: =I14/I8 -> 0.50555556
A17: Non-COGS OPEX 1 (e.g. Utilities) | B17: 300 | C17: 320 | D17: 340 | E17: =E8*E18 -> 365.88182 | F17: =F8*F18 -> 392.79017 | G17: =G8*G18 -> 421.97454 | H17: =H8*H18 -> 452.93463 | I17: =I8*I18 -> 486.1172
A18: % of revenue | B18: =B17/B8 -> 0.3 | C18: =C17/C8 -> 0.29090909 | D18: =D17/D8 -> 0.28333333 | E18: =D18-0.5% -> 0.27833333 | F18: =E18-0.5% -> 0.27333333 | G18: =F18-0.5% -> 0.26833333 | H18: =G18-0.5% -> 0.26333333 | I18: =H18-0.5% -> 0.25833333 | K18: 0.50 p.p. decrease y-o-y due to management estimate of cost efficiency measures
A20: Non-COGS OPEX 2 (e.g. Admin Salary) | B20: 30 | C20: 32 | D20: 34 | E20: =E11*E21 -> 43.872955 | F20: =F11*F21 -> 51.513791 | G20: =G11*G21 -> 60.260236 | H20: =H11*H21 -> 70.161867 | I20: =I11*I21 -> 81.411564
A21: % y-o-y growth | C21: =C20/B20-1 -> 0.066666667 | D21: =D20/C20-1 -> 0.0625 | E21: =D21+0.5% -> 0.0675 | F21: =E21+0.5% -> 0.0725 | G21: =F21+0.5% -> 0.0775 | H21: =G21+0.5% -> 0.0825 | I21: =H21+0.5% -> 0.0875 | K21: 0.50 p.p. increase y-o-y due to increasing wages in the operating country
A23: EBITDA | B23: =B14-B17-B20 -> 170 | C23: =C14-C17-C20 -> 198 | D23: =D14-D17-D20 -> 246 | E23: =E14-E17-E20 -> 254.82098 | F23: =F14-F17-F20 -> 282.19818 | G23: =G14-G17-G20 -> 312.78972 | H23: =H14-H17-H20 -> 346.46155 | I23: =I14-I17-I20 -> 383.79737
A24: % of revenue | B24: =B23/B8 -> 0.17 | C24: =C23/C8 -> 0.18 | D24: =D23/D8 -> 0.205 | E24: =E23/E8 -> 0.19384722 | F24: =F23/F8 -> 0.196375 | G24: =G23/G8 -> 0.19890278 | H24: =H23/H8 -> 0.20143056 | I24: =I23/I8 -> 0.20395833
A26: D&A | B26: 10 | C26: 11 | D26: 12 | E26: =D26*(1+E27) -> 13.090909 | F26: =E26*(1+F27) -> 14.280992 | G26: =F26*(1+G27) -> 15.579264 | H26: =G26*(1+H27) -> 16.99556 | I26: =H26*(1+I27) -> 18.540611
A27: % y-o-y growth | C27: =C26/B26-1 -> 0.1 | D27: =D26/C26-1 -> 0.090909091 | E27: =D27 -> 0.090909091 | F27: =E27 -> 0.090909091 | G27: =F27 -> 0.090909091 | H27: =G27 -> 0.090909091 | I27: =H27 -> 0.090909091 | K27: Assume 2014A level stays constant
A29: EBIT | B29: =B23-B26 -> 160 | C29: =C23-C26 -> 187 | D29: =D23-D26 -> 234 | E29: =E23-E26 -> 241.73008 | F29: =F23-F26 -> 267.91719 | G29: =G23-G26 -> 297.21046 | H29: =H23-H26 -> 329.46599 | I29: =I23-I26 -> 365.25676
A30: % of revenue | B30: =B29/B8 -> 0.16 | C30: =C29/C8 -> 0.17 | D30: =D29/D8 -> 0.195 | E30: =E29/E8 -> 0.18388872 | F30: =F29/F8 -> 0.1864372 | G30: =G29/G8 -> 0.18899593 | H30: =H29/H8 -> 0.19154944 | I30: =I29/I8 -> 0.19410545
A32: Interest Expense | B32: 30 | C32: 40 | D32: 50 | E32: =D32*(1+E33) -> 62.5 | F32: =E32*(1+F33) -> 78.125 | G32: =F32*(1+G33) -> 97.65625 | H32: =G32*(1+H33) -> 122.07031 | I32: =H32*(1+I33) -> 152.58789
A33: % growth | C33: =C32/B32-1 -> 0.33333333 | D33: =D32/C32-1 -> 0.25 | E33: =D33 -> 0.25 | F33: =E33 -> 0.25 | G33: =F33 -> 0.25 | H33: =G33 -> 0.25 | I33: =H33 -> 0.25 | K33: Assume 2014A level stays constant
A35: EBT | B35: =B29-B32 -> 130 | C35: =C29-C32 -> 147 | D35: =D29-D32 -> 184 | E35: =E29-E32 -> 179.23008 | F35: =F29-F32 -> 189.79219 | G35: =G29-G32 -> 199.55421 | H35: =H29-H32 -> 207.39567 | I35: =I29-I32 -> 212.66887
A36: % of revenue | B36: =B35/B8 -> 0.13 | C36: =C35/C8 -> 0.13363636 | D36: =D35/D8 -> 0.15333333 | E36: =E35/E8 -> 0.13634376 | F36: =F35/F8 -> 0.13207187 | G36: =G35/G8 -> 0.12689639 | H36: =H35/H8 -> 0.12057854 | I36: =I35/I8 -> 0.1130169
A38: Tax Expense | B38: 30 | C38: 34 | D38: 38 | E38: =E35*E39 -> 39.943423 | F38: =E38*(1+F39) -> 48.845261 | G38: =F38*(1+G39) -> 59.730972 | H38: =G38*(1+H39) -> 73.042686 | I38: =H38*(1+I39) -> 89.321064
A39: % of EBT | B39: =B38/B35 -> 0.23076923 | C39: =C38/C35 -> 0.23129252 | D39: =D38/D35 -> 0.20652174 | E39: =AVERAGE($B$39:$D$39) -> 0.22286116 | F39: =AVERAGE($B$39:$D$39) -> 0.22286116 | G39: =AVERAGE($B$39:$D$39) -> 0.22286116 | H39: =AVERAGE($B$39:$D$39) -> 0.22286116 | I39: =AVERAGE($B$39:$D$39) -> 0.22286116 | K39: % of EBT; simple average from 2012A-2014A
A41: Net Income | B41: =B35-B38 -> 100 | C41: =C35-C38 -> 113 | D41: =D35-D38 -> 146 | E41: =E35-E38 -> 139.28665 | F41: =F35-F38 -> 140.94693 | G41: =G35-G38 -> 139.82323 | H41: =H35-H38 -> 134.35299 | I41: =I35-I38 -> 123.34781
A42: % of revenue | B42: =B41/B8 -> 0.1 | C42: =C41/C8 -> 0.10272727 | D42: =D41/D8 -> 0.12166667 | E42: =E41/E8 -> 0.10595803 | F42: =F41/F8 -> 0.098081613 | G42: =G41/G8 -> 0.088913503 | H42: =H41/H8 -> 0.078111978 | I42: =I41/I8 -> 0.065549727

Sheet BAU v.2
A1: Notes: - Figures + assumptions are separated (either 2 different sheets or just separated within the sheet itself. - You can use this format if there are too many line items that Model 1 presentation becomes ugly and/or if it's not very meaningful to show y-o-y changes and margins directly. - When using this model, it is important to link the numbers at the assumption sheet and the main financial sheet carefully as chances of typo becomes bigger when you separate the two sheets. - 1 tip to overcome this is to ensure that they follow the same structure (e.g. if financial sheet has Revenue, COGS, Gross Profit, then in the assumption don't jump steps and put Revenue, COGS, then Non-COGS Operating Expenses)
A3: Income Statement
A4: Figures in USD millions unless otherwise stated
B6: 2012A | C6: 2013A | D6: 2014A | E6: 2015E | F6: 2016E | G6: 2017E | H6: 2018E | I6: 2019E
A8: Revenue | B8: 1000 | C8: 1100 | D8: 1200 | E8: =D8*(100%+E25) -> 1314.5455 | F8: =E8*(1+F25) -> 1437.0372 | G8: =F8*(1+G25) -> 1572.5759 | H8: =G8*(1+H25) -> 1720.0049 | I8: =H8*(1+I25) -> 1881.744
A9: COGS | B9: 500 | C9: 550 | D9: 580 | E9: =E8*E26 -> 649.9697 | F9: =F8*F26 -> 710.53506 | G9: =G8*G26 -> 777.55143 | H9: =H8*H26 -> 850.44688 | I9: =I8*I26 -> 930.41788
A10: Gross Profit | B10: =B8-B9 -> 500 | C10: =C8-C9 -> 550 | D10: =D8-D9 -> 620 | E10: =E8-E9 -> 664.57576 | F10: =F8-F9 -> 726.50213 | G10: =G8-G9 -> 795.0245 | H10: =H8-H9 -> 869.55804 | I10: =I8-I9 -> 951.32614
A11: Non-COGS OPEX 1 (e.g. Utilities) | B11: 300 | C11: 320 | D11: 340 | E11: =E8*E28 -> 365.88182 | F11: =F8*F28 -> 392.79017 | G11: =G8*G28 -> 421.97454 | H11: =H8*H28 -> 452.93463 | I11: =I8*I28 -> 486.1172
A12: Non-COGS OPEX 2 (e.g. Admin Salary) | B12: 30 | C12: 32 | D12: 34 | E12: =E9*E29 -> 43.872955 | F12: =F9*F29 -> 51.513791 | G12: =G9*G29 -> 60.260236 | H12: =H9*H29 -> 70.161867 | I12: =I9*I29 -> 81.411564
A13: EBITDA | B13: =B10-B11-B12 -> 170 | C13: =C10-C11-C12 -> 198 | D13: =D10-D11-D12 -> 246 | E13: =E10-E11-E12 -> 254.82098 | F13: =F10-F11-F12 -> 282.19818 | G13: =G10-G11-G12 -> 312.78972 | H13: =H10-H11-H12 -> 346.46155 | I13: =I10-I11-I12 -> 383.79737
A14: D&A | B14: 10 | C14: 11 | D14: 12 | E14: =D14*(1+E31) -> 13.090909 | F14: =E14*(1+F31) -> 14.280992 | G14: =F14*(1+G31) -> 15.579264 | H14: =G14*(1+H31) -> 16.99556 | I14: =H14*(1+I31) -> 18.540611
A15: EBIT | B15: =B13-B14 -> 160 | C15: =C13-C14 -> 187 | D15: =D13-D14 -> 234 | E15: =E13-E14 -> 241.73008 | F15: =F13-F14 -> 267.91719 | G15: =G13-G14 -> 297.21046 | H15: =H13-H14 -> 329.46599 | I15: =I13-I14 -> 365.25676
A16: Interest Expense | B16: 30 | C16: 40 | D16: 50 | E16: =D16*(1+E33) -> 62.5 | F16: =E16*(1+F33) -> 78.125 | G16: =F16*(1+G33) -> 97.65625 | H16: =G16*(1+H33) -> 122.07031 | I16: =H16*(1+I33) -> 152.58789
A17: EBT | B17: =B15-B16 -> 130 | C17: =C15-C16 -> 147 | D17: =D15-D16 -> 184 | E17: =E15-E16 -> 179.23008 | F17: =F15-F16 -> 189.79219 | G17: =G15-G16 -> 199.55421 | H17: =H15-H16 -> 207.39567 | I17: =I15-I16 -> 212.66887
A18: Tax Expense | B18: 30 | C18: 34 | D18: 38 | E18: =E17*E35 -> 39.943423 | F18: =E18*(1+F35) -> 48.845261 | G18: =F18*(1+G35) -> 59.730972 | H18: =G18*(1+H35) -> 73.042686 | I18: =H18*(1+I35) -> 89.321064
A19: Net Income | B19: =B17-B18 -> 100 | C19: =C17-C18 -> 113 | D19: =D17-D18 -> 146 | E19: =E17-E18 -> 139.28665 | F19: =F17-F18 -> 140.94693 | G19: =G17-G18 -> 139.82323 | H19: =H17-H18 -> 134.35299 | I19: =I17-I18 -> 123.34781
A22: Assumptions
B24: 2012A | C24: 2013A | D24: 2014A | E24: 2015E | F24: 2016E | G24: 2017E | H24: 2018E | I24: 2019E | K24: Assumptions
A25: Revenue | C25: =C8/B8-1 -> 0.1 | D25: =D8/C8-1 -> 0.090909091 | E25: =AVERAGE(C25:D25) -> 0.095454545 | F25: =AVERAGE(D25:E25) -> 0.093181818 | G25: =AVERAGE(E25:F25) -> 0.094318182 | H25: =AVERAGE(F25:G25) -> 0.09375 | I25: =AVERAGE(G25:H25) -> 0.094034091 | K25: y-o-y growth; 2Y moving average
A26: COGS | B26: =B9/B8 -> 0.5 | C26: =C9/C8 -> 0.5 | D26: =D9/D8 -> 0.48333333 | E26: =AVERAGE(B26:D26) -> 0.49444444 | F26: =E26 -> 0.49444444 | G26: =F26 -> 0.49444444 | H26: =G26 -> 0.49444444 | I26: =H26 -> 0.49444444 | K26: % of revenue; simple average from 2012A-2014A
A27: Gross Profit | B27: =B10/B8 -> 0.5 | C27: =C10/C8 -> 0.5 | D27: =D10/D8 -> 0.51666667 | E27: =E10/E8 -> 0.50555556 | F27: =F10/F8 -> 0.50555556 | G27: =G10/G8 -> 0.50555556 | H27: =H10/H8 -> 0.50555556 | I27: =I10/I8 -> 0.50555556
A28: Non-COGS OPEX 1 (e.g. Utilities) | B28: =B11/B8 -> 0.3 | C28: =C11/C8 -> 0.29090909 | D28: =D11/D8 -> 0.28333333 | E28: =D28-0.5% -> 0.27833333 | F28: =E28-0.5% -> 0.27333333 | G28: =F28-0.5% -> 0.26833333 | H28: =G28-0.5% -> 0.26333333 | I28: =H28-0.5% -> 0.25833333 | K28: % of revenue; 0.50 p.p. decrease y-o-y due to management estimate.
A29: Non-COGS OPEX 2 (e.g. Admin Salary) | C29: =C12/B12-1 -> 0.066666667 | D29: =D12/C12-1 -> 0.0625 | E29: =D29+0.5% -> 0.0675 | F29: =E29+0.5% -> 0.0725 | G29: =F29+0.5% -> 0.0775 | H29: =G29+0.5% -> 0.0825 | I29: =H29+0.5% -> 0.0875 | K29: y-o-y growth; 0.50 p.p. increase y-o-y due to increasing wages in the operating country
A30: EBITDA | B30: =B13/B8 -> 0.17 | C30: =C13/C8 -> 0.18 | D30: =D13/D8 -> 0.205 | E30: =E13/E8 -> 0.19384722 | F30: =F13/F8 -> 0.196375 | G30: =G13/G8 -> 0.19890278 | H30: =H13/H8 -> 0.20143056 | I30: =I13/I8 -> 0.20395833
A31: D&A | C31: =C14/B14-1 -> 0.1 | D31: =D14/C14-1 -> 0.090909091 | E31: =D31 -> 0.090909091 | F31: =E31 -> 0.090909091 | G31: =F31 -> 0.090909091 | H31: =G31 -> 0.090909091 | I31: =H31 -> 0.090909091 | K31: y-o-y growth; assume 2014A level stays constant
A32: EBIT | B32: =B15/B8 -> 0.16 | C32: =C15/C8 -> 0.17 | D32: =D15/D8 -> 0.195 | E32: =E15/E8 -> 0.18388872 | F32: =F15/F8 -> 0.1864372 | G32: =G15/G8 -> 0.18899593 | H32: =H15/H8 -> 0.19154944 | I32: =I15/I8 -> 0.19410545
A33: Interest Expense | C33: =C16/B16-1 -> 0.33333333 | D33: =D16/C16-1 -> 0.25 | E33: =D33 -> 0.25 | F33: =E33 -> 0.25 | G33: =F33 -> 0.25 | H33: =G33 -> 0.25 | I33: =H33 -> 0.25 | K33: y-o-y growth; assume 2014A level stays constant
A34: EBT | B34: =B17/B8 -> 0.13 | C34: =C17/C8 -> 0.13363636 | D34: =D17/D8 -> 0.15333333 | E34: =E17/E8 -> 0.13634376 | F34: =F17/F8 -> 0.13207187 | G34: =G17/G8 -> 0.12689639 | H34: =H17/H8 -> 0.12057854 | I34: =I17/I8 -> 0.1130169
A35: Tax Expense | B35: =B18/B17 -> 0.23076923 | C35: =C18/C17 -> 0.23129252 | D35: =D18/D17 -> 0.20652174 | E35: =AVERAGE($B$35:$D$35) -> 0.22286116 | F35: =AVERAGE($B$35:$D$35) -> 0.22286116 | G35: =AVERAGE($B$35:$D$35) -> 0.22286116 | H35: =AVERAGE($B$35:$D$35) -> 0.22286116 | I35: =AVERAGE($B$35:$D$35) -> 0.22286116 | K35: % of EBT; simple average from 2012A-2014A
A36: Net Income | B36: =B19/B8 -> 0.1 | C36: =C19/C8 -> 0.10272727 | D36: =D19/D8 -> 0.12166667 | E36: =E19/E8 -> 0.10595803 | F36: =F19/F8 -> 0.098081613 | G36: =G19/G8 -> 0.088913503 | H36: =H19/H8 -> 0.078111978 | I36: =I19/I8 -> 0.065549727

Sheet BAU v.3 (Quick)
A1: Notes: - Figures only with the only assumption being growth assumptions, which are based on CAGR (except Tax) - Assumption is that key line item will grow by the same rate for the next 5 years (that is, based on the CAGR). - You can use this format if you don't have enough time and/or it is not very meaningful to show y-o-y changes and margins. Can be used to very easily manipulate numbers when quick and dirty is needed (e.g. 30 mins left before submission). - How to manipulate? More CAGR = faster growth. Low CAGR = slow growth. Negative CAGR = decline. CAGR Formula = [(Figure at end)/(Figure at beginning)^(1/No of Years)] -1 - When calculating CAGR, count the number of years properly. For e.g. CAGR from 2012 to 2014 CAGR is 2 years, not 3 (although you have 2012A, 2013A and 2014A). This is because your figure from 2012A is your 'Figure at beginning' - Simple way to remember is to just deduct the end year with beginning year (2014-2012 = 2)
A3: Income Statement
A4: Figures in USD millions unless otherwise stated
B6: 2012A | C6: 2013A | D6: 2014A | E6: 2015E | F6: 2016E | G6: 2017E | H6: 2018E | I6: 2019E | K6: CAGR | M6: Assumptions
A8: Revenue | B8: 1000 | C8: 1100 | D8: 1200 | E8: =D8*(1+$K8) -> 1314.5341 | F8: =E8*(1+$K8) -> 1440 | G8: =F8*(1+$K8) -> 1577.441 | H8: =G8*(1+$K8) -> 1728 | I8: =H8*(1+$K8) -> 1892.9292 | K8: =(D8/B8)^(1/2)-1 -> 0.095445115 | M8: Assume CAGR from 2012-2014 is maintained at 9.54%
A9: COGS | B9: 500 | C9: 550 | D9: 580 | E9: =D9*(1+$K9) -> 635.35817 | F9: =E9*(1+$K9) -> 696 | G9: =F9*(1+$K9) -> 762.4298 | H9: =G9*(1+$K9) -> 835.2 | I9: =H9*(1+$K9) -> 914.91576 | K9: =K8 -> 0.095445115 | M9: Assume COGS will grow in line with revenue at 9.54% CAGR
A10: Gross Profit | B10: =B8-B9 -> 500 | C10: =C8-C9 -> 550 | D10: =D8-D9 -> 620 | E10: =E8-E9 -> 679.17597 | F10: =F8-F9 -> 744 | G10: =G8-G9 -> 815.01117 | H10: =H8-H9 -> 892.8 | I10: =I8-I9 -> 978.0134
A11: Non-COGS OPEX 1 (e.g. Utilities) | B11: 300 | C11: 320 | D11: 340 | E11: =D11*(1+$K11) -> 357 | F11: =E11*(1+$K11) -> 374.85 | G11: =F11*(1+$K11) -> 393.5925 | H11: =G11*(1+$K11) -> 413.27213 | I11: =H11*(1+$K11) -> 433.93573 | K11: 0.05 | M11: Assume CAGR from 2012-2014 at 6.46% will drop to 5% for the next 5 years as efficiency measures kick in
A12: Non-COGS OPEX 2 (e.g. Admin Salary) | B12: 30 | C12: 32 | D12: 34 | E12: =D12*(1+$K12) -> 36.38 | F12: =E12*(1+$K12) -> 38.9266 | G12: =F12*(1+$K12) -> 41.651462 | H12: =G12*(1+$K12) -> 44.567064 | I12: =H12*(1+$K12) -> 47.686759 | K12: 0.07 | M12: Assume CAGR from 2012-2014 at 6.46% will rise to 7% for the next 5 years as wages increase
A13: EBITDA | B13: =B10-B11-B12 -> 170 | C13: =C10-C11-C12 -> 198 | D13: =D10-D11-D12 -> 246 | E13: =E10-E11-E12 -> 285.79597 | F13: =F10-F11-F12 -> 330.2234 | G13: =G10-G11-G12 -> 379.7672 | H13: =H10-H11-H12 -> 434.96081 | I13: =I10-I11-I12 -> 496.39091
A14: D&A | B14: 10 | C14: 11 | D14: 12 | E14: =D14*(1+$K14) -> 12 | F14: =E14*(1+$K14) -> 12 | G14: =F14*(1+$K14) -> 12 | H14: =G14*(1+$K14) -> 12 | I14: =H14*(1+$K14) -> 12 | K14: =J13 -> 0 | M14: y-o-y growth; assume 2014A level stays constant
A15: EBIT | B15: =B13-B14 -> 160 | C15: =C13-C14 -> 187 | D15: =D13-D14 -> 234 | E15: =E13-E14 -> 273.79597 | F15: =F13-F14 -> 318.2234 | G15: =G13-G14 -> 367.7672 | H15: =H13-H14 -> 422.96081 | I15: =I13-I14 -> 484.39091
A16: Interest Expense | B16: 30 | C16: 40 | D16: 50 | E16: =D16*(1+$K16) -> 49.5 | F16: =E16*(1+$K16) -> 49.005 | G16: =F16*(1+$K16) -> 48.51495 | H16: =G16*(1+$K16) -> 48.029801 | I16: =H16*(1+$K16) -> 47.549502 | K16: -0.01 | M16: Assume there will be gradual decrease of interest rate at 1% CAGR
A17: EBT | B17: =B15-B16 -> 130 | C17: =C15-C16 -> 147 | D17: =D15-D16 -> 184 | E17: =E15-E16 -> 224.29597 | F17: =F15-F16 -> 269.2184 | G17: =G15-G16 -> 319.25225 | H17: =H15-H16 -> 374.93101 | I17: =I15-I16 -> 436.84141
A18: Tax Expense | B18: 30 | C18: 34 | D18: 38 | E18: =AVERAGE(($B$18/$B$17),($C$18/$C$17),($D$18/$D$17))*E17 -> 49.986861 | F18: =AVERAGE(($B$18/$B$17),($C$18/$C$17),($D$18/$D$17))*F17 -> 59.998326 | G18: =AVERAGE(($B$18/$B$17),($C$18/$C$17),($D$18/$D$17))*G17 -> 71.148928 | H18: =AVERAGE(($B$18/$B$17),($C$18/$C$17),($D$18/$D$17))*H17 -> 83.557561 | I18: =AVERAGE(($B$18/$B$17),($C$18/$C$17),($D$18/$D$17))*I17 -> 97.354984 | M18: Assume average tax rate as % of EBT from 2012A-2014A stays constant
A19: Net Income | B19: =B17-B18 -> 100 | C19: =C17-C18 -> 113 | D19: =D17-D18 -> 146 | E19: =E17-E18 -> 174.30911 | F19: =F17-F18 -> 209.22007 | G19: =G17-G18 -> 248.10333 | H19: =H17-H18 -> 291.37345 | I19: =I17-I18 -> 339.48642

Sheet REC>

Sheet REC v.1 (Top-Down)
A1: Notes: - So, personally, I don't like to mix my BAU with Revenue/Costs from Rec. Instead, I create a separate sheet and later on, I only add the key incremental figures to the original BAU model (e.g. Incremental Revenue, Incremental COGS, and Incremental Non-COGS OPEX) - Why? 2 reasons: the original BAU model is a 'high level' model and should only contain distilled, key figures, while the second reason is that isolating the entire Revenue/Cost implication of your recommendation makes it easier for you to create graphs to show incremental changes. - I generally prefer Top Down to Bottom Up approach; reason is for most cases you can probably find market size and proxy your company's shares. Second reason is because sometimes within a particular market there are too many variables you need to consider (e.g. no. of stores, frequency of buying, average price, etc. etc.) that I think it is quicker - especially for mature companies in mature industry - to use Top Down. - Once you are done with this REC Model, you combine it with the Original BAU Model (next sheet) - Take note that, some UPFRONT investments are capitalised (e.g. factory - see my cost breakdown) and will NOT go through your final Income Statement! Instead, these new investments will add only to the D&A.
A3: Revenue Breakdown (assume you have two countries, and two products in each country)
A4: Figures in USD millions unless otherwise stated
B6: 2012A | C6: 2013A | D6: 2014A | E6: 2015E | F6: 2016E | G6: 2017E | H6: 2018E | I6: 2019E | K6: Source/Assumption
A7: Singapore
A9: Product 1 in Industry 1 (Rec 1) | B9: 600 | C9: 650 | D9: 700 | E9: =E38*E40 -> 775.91509 | F9: =F38*F40 -> 855.43019 | G9: =G38*G40 -> 938.54528 | H9: =H38*H40 -> 1025.2604 | I9: =I38*I40 -> 1115.5755 | K9: Market penetration; share rises 0.20% annually because Jive's strategy to improve product and marketing is effective
A10: % y-o-y growth | C10: =C9/B9-1 -> 0.083333333 | D10: =D9/C9-1 -> 0.076923077 | E10: =E9/D9-1 -> 0.10845013 | F10: =F9/E9-1 -> 0.10247912 | G10: =G9/F9-1 -> 0.09716175 | H10: =H9/G9-1 -> 0.092393085 | I10: =I9/H9-1 -> 0.08808991 | K10: Note: for market penetration, make sure that the overall growth (due to increase in share) is faster than the company's BAU growth
A11: Product 2 in Industry 2 (New Product; Rec 2) | B11: 0 | C11: 0 | D11: 0 | E11: =E42*E44 -> 99.75 | F11: =F42*F44 -> 207 | G11: =G42*G44 -> 321.75 | H11: =H42*H44 -> 444 | I11: =I42*I44 -> 577.5 | K11: Market entry (initial 0% share); rise 0.15% annually because DVM's market entry strategy is good
A12: % y-o-y growth | F12: =F11/E11-1 -> 1.075188 | G12: =G11/F11-1 -> 0.55434783 | H12: =H11/G11-1 -> 0.37995338 | I12: =I11/H11-1 -> 0.30067568
A13: Country Revenue | B13: =B11+B9 -> 600 | C13: =C11+C9 -> 650 | D13: =D11+D9 -> 700 | E13: =E11+E9 -> 875.66509 | F13: =F11+F9 -> 1062.4302 | G13: =G11+G9 -> 1260.2953 | H13: =H11+H9 -> 1469.2604 | I13: =I11+I9 -> 1693.0755
A14: % y-o-y growth | C14: =C13/B13-1 -> 0.083333333 | D14: =D13/C13-1 -> 0.076923077 | E14: =E13/D13-1 -> 0.25095013 | F14: =F13/E13-1 -> 0.2132837 | G14: =G13/F13-1 -> 0.18623821 | H14: =H13/G13-1 -> 0.16580646 | I14: =I13/H13-1 -> 0.15233181
A16: Indonesia
A18: Product 1 in Industry 1 | B18: 400 | C18: 450 | D18: 500 | E18: =D18*(1+'BAU v.1'!E9) -> 547.72727 | F18: =E18*(1+'BAU v.1'!F9) -> 598.7655 | G18: =F18*(1+'BAU v.1'!G9) -> 655.23997 | H18: =G18*(1+'BAU v.1'!H9) -> 716.66872 | I18: =H18*(1+'BAU v.1'!I9) -> 784.06001 | K18: Not covered by recommendation; grow at same rate as revenue growth BAU (for e.g. this is linked to BAU Model 1 revenue growth % y-o-y)
A19: % y-o-y growth | C19: =C18/B18-1 -> 0.125 | D19: =D18/C18-1 -> 0.11111111 | E19: =E18/D18-1 -> 0.095454545 | F19: =F18/E18-1 -> 0.093181818 | G19: =G18/F18-1 -> 0.094318182 | H19: =H18/G18-1 -> 0.09375 | I19: =I18/H18-1 -> 0.094034091
A20: Product 2 in Industry 2 (New Product; Rec 3) | B20: 0 | C20: 0 | D20: 0 | E20: =E51*E53 -> 5.5 | F20: =F51*F53 -> 11.4 | G20: =G51*G53 -> 23.6 | H20: =H51*H53 -> 48.8 | I20: =I51*I53 -> 100.8 | K20: Market entry (initial 0% share); rise 0.30% annually because DVM's market entry strategy is good and there is fewer quality competitors compared to Singapore
A21: % y-o-y growth | F21: =F20/E20-1 -> 1.0727273 | G21: =G20/F20-1 -> 1.0701754 | H21: =H20/G20-1 -> 1.0677966 | I21: =I20/H20-1 -> 1.0655738
A22: Country Revenue | B22: =B18+B20 -> 400 | C22: =C18+C20 -> 450 | D22: =D18+D20 -> 500 | E22: =E18+E20 -> 553.22727 | F22: =F18+F20 -> 610.1655 | G22: =G18+G20 -> 678.83997 | H22: =H18+H20 -> 765.46872 | I22: =I18+I20 -> 884.86001
A23: % y-o-y growth | C23: =C22/B22-1 -> 0.125 | D23: =D22/C22-1 -> 0.11111111 | E23: =E22/D22-1 -> 0.10645455 | F23: =F22/E22-1 -> 0.10292013 | G23: =G22/F22-1 -> 0.11255057 | H23: =H22/G22-1 -> 0.12761291 | I23: =I22/H22-1 -> 0.15597148
A26: Total Revenue (with Recommendation) | B26: =B22+B13 -> 1000 | C26: =C22+C13 -> 1100 | D26: =D22+D13 -> 1200 | E26: =E22+E13 -> 1428.8924 | F26: =F22+F13 -> 1672.5957 | G26: =G22+G13 -> 1939.1353 | H26: =H22+H13 -> 2234.7291 | I26: =I22+I13 -> 2577.9355
A27: % y-o-y growth | C27: =C26/B26-1 -> 0.1 | D27: =D26/C26-1 -> 0.090909091 | E27: =E26/D26-1 -> 0.19074364 | F27: =F26/E26-1 -> 0.17055401 | G27: =G26/F26-1 -> 0.15935684 | H27: =H26/G26-1 -> 0.15243591 | I27: =I26/H26-1 -> 0.15357852
A29: Total Revenue (BAU) | B29: ='BAU v.1'!B8 -> 1000 | C29: ='BAU v.1'!C8 -> 1100 | D29: ='BAU v.1'!D8 -> 1200 | E29: ='BAU v.1'!E8 -> 1314.5455 | F29: ='BAU v.1'!F8 -> 1437.0372 | G29: ='BAU v.1'!G8 -> 1572.5759 | H29: ='BAU v.1'!H8 -> 1720.0049 | I29: ='BAU v.1'!I8 -> 1881.744 | K29: Linked to BAU Revenue from BAU Model 1.
A30: % y-o-y growth | C30: =C29/B29-1 -> 0.1 | D30: =D29/C29-1 -> 0.090909091 | E30: =E29/D29-1 -> 0.095454545 | F30: =F29/E29-1 -> 0.093181818 | G30: =G29/F29-1 -> 0.094318182 | H30: =H29/G29-1 -> 0.09375 | I30: =I29/H29-1 -> 0.094034091
A31: Incremental Revenue from Recommendation | B31: =B26-B29 -> 0 | C31: =C26-C29 -> 0 | D31: =D26-D29 -> 0 | E31: =E26-E29 -> 114.34691 | F31: =F26-F29 -> 235.55849 | G31: =G26-G29 -> 366.55933 | H31: =H26-H29 -> 514.72418 | I31: =I26-I29 -> 696.19146
A32: % y-o-y growth | F32: =F31/E31-1 -> 1.0600337 | G32: =G31/F31-1 -> 0.55612867 | H32: =H31/G31-1 -> 0.40420428 | I32: =I31/H31-1 -> 0.35255248
A34: Revenue Assumptions
B36: 2012A | C36: 2013A | D36: 2014A | E36: 2015E | F36: 2016E | G36: 2017E | H36: 2018E | I36: 2019E
A37: Singapore
A38: Industry 1 | B38: 5000 | C38: 5100 | D38: 5300 | E38: 5500 | F38: 5700 | G38: 5900 | H38: 6100 | I38: 6300 | K38: Euromonitor
A39: % growth | C39: =C38/B38-1 -> 0.02 | D39: =D38/C38-1 -> 0.039215686 | E39: =E38/D38-1 -> 0.037735849 | F39: =F38/E38-1 -> 0.036363636 | G39: =G38/F38-1 -> 0.035087719 | H39: =H38/G38-1 -> 0.033898305 | I39: =I38/H38-1 -> 0.032786885
A40: % share | C40: =C9/C38 -> 0.12745098 | D40: =D9/D38 -> 0.13207547 | E40: =D40+0.9% -> 0.14107547 | F40: =E40+0.9% -> 0.15007547 | G40: =F40+0.9% -> 0.15907547 | H40: =G40+0.9% -> 0.16807547 | I40: =H40+0.9% -> 0.17707547 | K40: Market penetration; share rises 0.20% annually because Jive's strategy to improve product and marketing is effective
A42: Industry 2 (New Market) | B42: 6150 | C42: 6300 | D42: 6450 | E42: 6650 | F42: 6900 | G42: 7150 | H42: 7400 | I42: 7700 | K42: Euromonitor
A43: % growth | C43: =C42/B42-1 -> 0.024390244 | D43: =D42/C42-1 -> 0.023809524 | E43: =E42/D42-1 -> 0.031007752 | F43: =F42/E42-1 -> 0.037593985 | G43: =G42/F42-1 -> 0.036231884 | H43: =H42/G42-1 -> 0.034965035 | I43: =I42/H42-1 -> 0.040540541
A44: % share | C44: 0 | D44: 0 | E44: =D44+1.5% -> 0.015 | F44: =E44+1.5% -> 0.03 | G44: =F44+1.5% -> 0.045 | H44: =G44+1.5% -> 0.06 | I44: =H44+1.5% -> 0.075 | K44: Market entry (initial 0% share); rise 1.5% annually because DVM's market entry strategy is good
A46: Indonesia
A47: Industry 1 | B47: 5000 | C47: 5100 | D47: 5300 | E47: 5500 | F47: 5700 | G47: 5900 | H47: 6100 | I47: 6300 | K47: Euromonitor
A48: % growth | C48: =C47/B47-1 -> 0.02 | D48: =D47/C47-1 -> 0.039215686 | E48: =E47/D47-1 -> 0.037735849 | F48: =F47/E47-1 -> 0.036363636 | G48: =G47/F47-1 -> 0.035087719 | H48: =H47/G47-1 -> 0.033898305 | I48: =I47/H47-1 -> 0.032786885
A49: % share | C49: =C18/C47 -> 0.088235294 | D49: =D18/D47 -> 0.094339623 | K49: Not covered by recommendation; grow at same rate as revenue growth BAU (for e.g. this is linked to BAU Model 1 revenue growth % y-o-y)
A51: Industry 2 (New Market) | B51: 5000 | C51: 5100 | D51: 5300 | E51: 5500 | F51: 5700 | G51: 5900 | H51: 6100 | I51: 6300 | K51: Euromonitor
A52: % growth | C52: =C51/B51-1 -> 0.02 | D52: =D51/C51-1 -> 0.039215686 | E52: =E51/D51-1 -> 0.037735849 | F52: =F51/E51-1 -> 0.036363636 | G52: =G51/F51-1 -> 0.035087719 | H52: =H51/G51-1 -> 0.033898305 | I52: =I51/H51-1 -> 0.032786885
A53: % share | C53: 0 | D53: 0 | E53: 0.001 | F53: =E53*2 -> 0.002 | G53: =F53*2 -> 0.004 | H53: =G53*2 -> 0.008 | I53: =H53*2 -> 0.016 | K53: Market entry (initial 0% share); exponential growth (double each year) because WKG's market entry strategy is good and there is fewer quality competitors compared to Singapore
...

Sheet REC v.2 (Bottom Up)
A1: Notes: - I lazy make, as I said, I personally prefer top-down as it is faster and more intuitive for me. You can ask Eliel how to do bottom up. Basically, identify every single variable that affects your revenue (primarily quantity of people buying * selling price), then the costs are pretty much the same as previous version.
B5: 2012A | C5: 2013A | D5: 2014A | E5: 2015E | F5: 2016E | G5: 2017E | I5: Assumptions
A7: Number of People | E7: 1000 | F7: =E7*(1+F8) -> 1200 | G7: =F7*(1+G8) -> 1440 | I7: 1000 people in first year
A8: % growth | F8: 0.2 | G8: 0.2 | I8: 20% growth yoy
A10: Unit Price | E10: 10 | F10: =E10*(1+F11) -> 11 | G10: =F10*(1+G11) -> 12.1 | I10: Entry price set at $10
A11: % growth | F11: 0.1 | G11: 0.1 | I11: 10% growth yoy
A13: Revenue | E13: =E10*E7 -> 10000 | F13: =F10*F7 -> 13200 | G13: =G10*G7 -> 17424
A14: % of Revenue | F14: =F13/E13-1 -> 0.32 | G14: =G13/F13-1 -> 0.32
A17: COGS | E17: =E13*E18 -> 3000 | F17: =F13*F18 -> 3960 | G17: =G13*G18 -> 4356
A18: % of Revenue | E18: 0.3 | F18: 0.3 | G18: 0.25 | I18: Stable at 30% for the first 2 years, then cost efficiency by third year to 25%
A21: Marketing | E21: 2000 | F21: =E21*(1+F22) -> 2200 | G21: =F21*(1+G22) -> 2420 | I21: Initial budget at 2000
A22: % growth | F22: 0.1 | G22: 0.1 | I22: 10% growth yoy
A24: Selling Expenses | E24: 200 | F24: =E24*(1+F25) -> 220 | G24: =F24*(1+G25) -> 242 | I24: Initial budget at 200
A25: % growth | F25: 0.1 | G25: 0.1 | I25: 10% growth yoy
A27: OPEX | E27: =E21+E24 -> 2200 | F27: =F21+F24 -> 2420 | G27: =G21+G24 -> 2662
A28: % of Revenue | E28: =E27/E13 -> 0.22 | F28: =F27/F13 -> 0.18333333 | G28: =G27/G13 -> 0.15277778

Sheet MERGE>

Sheet MERGE v.1
A1: Notes: - Figures + assumptions are separated (either 2 different sheets or just separated within the sheet itself. - You can use this format if there are too many line items that Model 1 presentation becomes ugly and/or if it's not very meaningful to show y-o-y changes and margins directly. - When using this model, it is important to link the numbers at the assumption sheet and the main financial sheet carefully as chances of typo becomes bigger when you separate the two sheets. - 1 tip to overcome this is to ensure that they follow the same structure (e.g. if financial sheet has Revenue, COGS, Gross Profit, then in the assumption don't jump steps and put Revenue, COGS, then Non-COGS Operating Expenses)
A3: Income Statement
A4: Figures in USD millions unless otherwise stated
B6: 2012A | C6: 2013A | D6: 2014A | E6: 2015E | F6: 2016E | G6: 2017E | H6: 2018E | I6: 2019E
A8: Revenue (BAU) | B8: 1000 | C8: 1100 | D8: 1200 | E8: =D8*(100%+E41) -> 1314.5455 | F8: =E8*(1+F41) -> 1437.0372 | G8: =F8*(1+G41) -> 1572.5759 | H8: =G8*(1+H41) -> 1720.0049 | I8: =H8*(1+I41) -> 1881.744
A9: Incremental Revenue (REC) | E9: ='REC v.1 (Top-Down)'!E31 -> 114.34691 | F9: ='REC v.1 (Top-Down)'!F31 -> 235.55849 | G9: ='REC v.1 (Top-Down)'!G31 -> 366.55933 | H9: ='REC v.1 (Top-Down)'!H31 -> 514.72418 | I9: ='REC v.1 (Top-Down)'!I31 -> 696.19146 | K9: Linked to REC Model 2 (Top Down)
A11: Total Revenue | B11: =B8+B9 -> 1000 | C11: =C8+C9 -> 1100 | D11: =D8+D9 -> 1200 | E11: =E8+E9 -> 1428.8924 | F11: =F8+F9 -> 1672.5957 | G11: =G8+G9 -> 1939.1353 | H11: =H8+H9 -> 2234.7291 | I11: =I8+I9 -> 2577.9355
A13: COGS (BAU) | B13: 500 | C13: 550 | D13: 580 | E13: =E8*E44 -> 649.9697 | F13: =F8*F44 -> 710.53506 | G13: =G8*G44 -> 777.55143 | H13: =H8*H44 -> 850.44688 | I13: =I8*I44 -> 930.41788
A14: Incremental COGS (REC) | E14: ='REC v.1 (Top-Down)'!E61 -> 34.304074 | F14: ='REC v.1 (Top-Down)'!F61 -> 68.311963 | G14: ='REC v.1 (Top-Down)'!G61 -> 102.63661 | H14: ='REC v.1 (Top-Down)'!H61 -> 138.97553 | I14: ='REC v.1 (Top-Down)'!I61 -> 181.00978 | K14: Linked to REC Model 2 (Top Down)
A16: Gross Profit | B16: =B8+B9-B13-B14 -> 500 | C16: =C8+C9-C13-C14 -> 550 | D16: =D8+D9-D13-D14 -> 620 | E16: =E8+E9-E13-E14 -> 744.6186 | F16: =F8+F9-F13-F14 -> 893.74867 | G16: =G8+G9-G13-G14 -> 1058.9472 | H16: =H8+H9-H13-H14 -> 1245.3067 | I16: =I8+I9-I13-I14 -> 1466.5078 | K16: Update formula
A18: Non-COGS OPEX 1 (e.g. Utilities) | B18: 300 | C18: 320 | D18: 340 | E18: =E8*E47 -> 365.88182 | F18: =F8*F47 -> 392.79017 | G18: =G8*G47 -> 421.97454 | H18: =H8*H47 -> 452.93463 | I18: =I8*I47 -> 486.1172
A19: Non-COGS OPEX 2 (e.g. Admin Salary) | B19: 30 | C19: 32 | D19: 34 | E19: =E13*E48 -> 43.872955 | F19: =F13*F48 -> 51.513791 | G19: =G13*G48 -> 60.260236 | H19: =H13*H48 -> 70.161867 | I19: =I13*I48 -> 81.411564
A20: Incremental Non-COGS OPEX | D20: ='REC v.1 (Top-Down)'!D80 -> 73 | E20: ='REC v.1 (Top-Down)'!E80 -> 83.380092 | F20: ='REC v.1 (Top-Down)'!F80 -> 126.68885 | G20: ='REC v.1 (Top-Down)'!G80 -> 168.05276 | H20: ='REC v.1 (Top-Down)'!H80 -> 213.02252 | I20: ='REC v.1 (Top-Down)'!I80 -> 266.45968 | K20: Linked to REC Model 2 (Top Down)
A22: EBITDA | B22: =B16-B18-B19-B20 -> 170 | C22: =C16-C18-C19-C20 -> 198 | D22: =D16-D18-D19-D20 -> 173 | E22: =E16-E18-E19-E20 -> 251.48373 | F22: =F16-F18-F19-F20 -> 322.75586 | G22: =G16-G18-G19-G20 -> 408.65967 | H22: =H16-H18-H19-H20 -> 509.18767 | I22: =I16-I18-I19-I20 -> 632.51938 | K22: Update formula
A24: D&A (BAU) | B24: 10 | C24: 11 | D24: 12 | E24: =D24*(1+E51) -> 13.090909 | F24: =E24*(1+F51) -> 14.280992 | G24: =F24*(1+G51) -> 15.579264 | H24: =G24*(1+H51) -> 16.99556 | I24: =H24*(1+I51) -> 18.540611
A25: Incremental D&A | D25: ='REC v.1 (Top-Down)'!D89 -> 30 | E25: ='REC v.1 (Top-Down)'!E89 -> 30 | F25: ='REC v.1 (Top-Down)'!F89 -> 30 | G25: ='REC v.1 (Top-Down)'!G89 -> 30 | H25: ='REC v.1 (Top-Down)'!H89 -> 30 | I25: ='REC v.1 (Top-Down)'!I89 -> 30 | K25: Linked to REC Model 2 (Top Down)
A27: EBIT | B27: =B22-B24-B25 -> 160 | C27: =C22-C24-C25 -> 187 | D27: =D22-D24-D25 -> 131 | E27: =E22-E24-E25 -> 208.39282 | F27: =F22-F24-F25 -> 278.47487 | G27: =G22-G24-G25 -> 363.08041 | H27: =H22-H24-H25 -> 462.19211 | I27: =I22-I24-I25 -> 583.97877 | K27: Update formula
A29: Interest Expense | B29: 30 | C29: 40 | D29: 50 | E29: =D29*(1+E54) -> 62.5 | F29: =E29*(1+F54) -> 78.125 | G29: =F29*(1+G54) -> 97.65625 | H29: =G29*(1+H54) -> 122.07031 | I29: =H29*(1+I54) -> 152.58789
A31: EBT | B31: =B27-B29 -> 130 | C31: =C27-C29 -> 147 | D31: =D27-D29 -> 81 | E31: =E27-E29 -> 145.89282 | F31: =F27-F29 -> 200.34987 | G31: =G27-G29 -> 265.42416 | H31: =H27-H29 -> 340.1218 | I31: =I27-I29 -> 431.39088
A33: Tax Expense | B33: 30 | C33: 34 | D33: 38 | E33: =E31*E56 -> 45.285013 | F33: =E33*(1+F56) -> 59.341444 | G33: =F33*(1+G56) -> 77.76098 | H33: =G33*(1+H56) -> 101.89792 | I33: =H33*(1+I56) -> 133.52696
A35: Net Income | B35: =B31-B33 -> 100 | C35: =C31-C33 -> 113 | D35: =D31-D33 -> 43 | E35: =E31-E33 -> 100.60781 | F35: =F31-F33 -> 141.00842 | G35: =G31-G33 -> 187.66318 | H35: =H31-H33 -> 238.22387 | I35: =I31-I33 -> 297.86392
A38: Assumptions (feel free to tweak the original BAU-related assumptions if you feel there are certain synergies/cannibalisation that wasn't already included in your REC model)
B40: 2012A | C40: 2013A | D40: 2014A | E40: 2015E | F40: 2016E | G40: 2017E | H40: 2018E | I40: 2019E | K40: Assumptions
A41: Revenue (BAU) | C41: =C8/B8-1 -> 0.1 | D41: =D8/C8-1 -> 0.090909091 | E41: =AVERAGE(C41:D41) -> 0.095454545 | F41: =AVERAGE(D41:E41) -> 0.093181818 | G41: =AVERAGE(E41:F41) -> 0.094318182 | H41: =AVERAGE(F41:G41) -> 0.09375 | I41: =AVERAGE(G41:H41) -> 0.094034091 | K41: y-o-y growth; 2Y moving average
A42: Incremental Revenue (REC) | F42: =F9/E9-1 -> 1.0600337 | G42: =G9/F9-1 -> 0.55612867 | H42: =H9/G9-1 -> 0.40420428 | I42: =I9/H9-1 -> 0.35255248
A43: Total Revenue | C43: =C11/B11-1 -> 0.1 | D43: =D11/C11-1 -> 0.090909091 | E43: =E11/D11-1 -> 0.19074364 | F43: =F11/E11-1 -> 0.17055401 | G43: =G11/F11-1 -> 0.15935684 | H43: =H11/G11-1 -> 0.15243591 | I43: =I11/H11-1 -> 0.15357852
A44: COGS (BAU) | B44: =B13/B8 -> 0.5 | C44: =C13/C8 -> 0.5 | D44: =D13/D8 -> 0.48333333 | E44: =AVERAGE(B44:D44) -> 0.49444444 | F44: =E44 -> 0.49444444 | G44: =F44 -> 0.49444444 | H44: =G44 -> 0.49444444 | I44: =H44 -> 0.49444444 | K44: % of revenue; simple average from 2012A-2014A
A45: Incremental COGS (REC) | F45: =F14/E14-1 -> 0.99136592 | G45: =G14/F14-1 -> 0.50246906 | H45: =H14/G14-1 -> 0.35405413 | I45: =I14/H14-1 -> 0.30245795
A46: Gross Profit | B46: =B16/B11 -> 0.5 | C46: =C16/C11 -> 0.5 | D46: =D16/D11 -> 0.51666667 | E46: =E16/E11 -> 0.52111595 | F46: =F16/F11 -> 0.5343483 | G46: =G16/G11 -> 0.5460925 | H46: =H16/H11 -> 0.55725175 | I46: =I16/I11 -> 0.5688691
A47: Non-COGS OPEX 1 (e.g. Utilities) | B47: =B18/B8 -> 0.3 | C47: =C18/C8 -> 0.29090909 | D47: =D18/D8 -> 0.28333333 | E47: =D47-0.5% -> 0.27833333 | F47: =E47-0.5% -> 0.27333333 | G47: =F47-0.5% -> 0.26833333 | H47: =G47-0.5% -> 0.26333333 | I47: =H47-0.5% -> 0.25833333 | K47: % of revenue; 0.50 p.p. decrease y-o-y due to management estimate.
A48: Non-COGS OPEX 2 (e.g. Admin Salary) | C48: =C19/B19-1 -> 0.066666667 | D48: =D19/C19-1 -> 0.0625 | E48: =D48+0.5% -> 0.0675 | F48: =E48+0.5% -> 0.0725 | G48: =F48+0.5% -> 0.0775 | H48: =G48+0.5% -> 0.0825 | I48: =H48+0.5% -> 0.0875 | K48: y-o-y growth; 0.50 p.p. increase y-o-y due to increasing wages in the operating country
A49: Incremental Non-COGS OPEX (REC) | E49: =E20/D20-1 -> 0.14219304 | F49: =F20/E20-1 -> 0.51941365 | G49: =G20/F20-1 -> 0.32650001 | H49: =H20/G20-1 -> 0.26759312 | I49: =I20/H20-1 -> 0.25085213
A50: EBITDA | B50: =B22/B8 -> 0.17 | C50: =C22/C8 -> 0.18 | D50: =D22/D8 -> 0.14416667 | E50: =E22/E8 -> 0.19130851 | F50: =F22/F8 -> 0.22459813 | G50: =G22/G8 -> 0.25986642 | H50: =H22/H8 -> 0.2960385 | I50: =I22/I8 -> 0.33613466
A51: D&A (BAU) | C51: =C24/B24-1 -> 0.1 | D51: =D24/C24-1 -> 0.090909091 | E51: =D51 -> 0.090909091 | F51: =E51 -> 0.090909091 | G51: =F51 -> 0.090909091 | H51: =G51 -> 0.090909091 | I51: =H51 -> 0.090909091 | K51: y-o-y growth; assume 2014A level stays constant
A52: Incremental D&A | E52: =E25/D25-1 -> 0 | F52: =F25/E25-1 -> 0 | G52: =G25/F25-1 -> 0 | H52: =H25/G25-1 -> 0 | I52: =I25/H25-1 -> 0
A53: EBIT | B53: =B27/B8 -> 0.16 | C53: =C27/C8 -> 0.17 | D53: =D27/D8 -> 0.10916667 | E53: =E27/E8 -> 0.15852843 | F53: =F27/F8 -> 0.19378404 | G53: =G27/G8 -> 0.23088259 | H53: =H27/H8 -> 0.26871557 | I53: =I27/I8 -> 0.31033911
A54: Interest Expense | C54: =C29/B29-1 -> 0.33333333 | D54: =D29/C29-1 -> 0.25 | E54: =D54 -> 0.25 | F54: =E54 -> 0.25 | G54: =F54 -> 0.25 | H54: =G54 -> 0.25 | I54: =H54 -> 0.25 | K54: y-o-y growth; assume 2014A level stays constant
A55: EBT | B55: =B31/B8 -> 0.13 | C55: =C31/C8 -> 0.13363636 | D55: =D31/D8 -> 0.0675 | E55: =E31/E8 -> 0.11098347 | F55: =F31/F8 -> 0.13941871 | G55: =G31/G8 -> 0.16878305 | H55: =H31/H8 -> 0.19774467 | I55: =I31/I8 -> 0.22925056
A56: Tax Expense | B56: =B33/B31 -> 0.23076923 | C56: =C33/C31 -> 0.23129252 | D56: =D33/D31 -> 0.4691358 | E56: =AVERAGE($B$56:$D$56) -> 0.31039918 | F56: =AVERAGE($B$56:$D$56) -> 0.31039918 | G56: =AVERAGE($B$56:$D$56) -> 0.31039918 | H56: =AVERAGE($B$56:$D$56) -> 0.31039918 | I56: =AVERAGE($B$56:$D$56) -> 0.31039918 | K56: % of EBT; simple average from 2012A-2014A
A57: Net Income | B57: =B35/B8 -> 0.1 | C57: =C35/C8 -> 0.10272727 | D57: =D35/D8 -> 0.035833333 | E57: =E35/E8 -> 0.076534295 | F57: =F35/F8 -> 0.098124408 | G57: =G35/G8 -> 0.11933489 | H57: =H35/H8 -> 0.13850186 | I57: =I35/I8 -> 0.15829141

Sheet CHARTS>

Sheet CHARTS v.1
A2: Revenue
A29: For graphs, put axis label (except when it's years), put axis title
A30: You are allowed to skip the 2 d.p. rule as the decimals will clutter the graph
A31: Do not put all numbers; just the essentials
A33: Incremental EBIT
A61: Show EBIT to remove distortion from tax/interest expense and purely evaluate from operational standpoint.
A62: Generally, your recommendation will probably make losses for the first 1-2 years before hitting break even point.
A93: Waterfall chart is a useful tool to breakdown cost.
